<?xml version="1.0" ?>
<robot xmlns:xacro="http://ros.org/wiki/xacro">
  <xacro:include filename="$(find sciurus17_description)/urdf/vehicle/sciurus_vehicle.gazebo.xacro"/>
<!--
  <xacro:include filename="$(find sciurus_vehicle_description)/urdf/caster/caster.transmission.xacro"/>
-->

  <xacro:macro name="vehicle" params="name">
    <caster_trans prefix="test" interface="test"/>

    <link name="base_footprint"/>

    <joint name="base_joint" type="fixed">
      <parent link="base_footprint"/>
      <child link="vehicle_base_link"/>
      <origin xyz="0.0 0.0 0.10975" rpy="0 0 0"/>
    </joint>

    <link name="vehicle_base_link">
      <visual>
        <origin xyz="-0.0575 0 0.0" rpy="0 0 0"/>
        <geometry>
          <mesh filename="package://sciurus17_description/meshes/vehicle/bases/sciurus_vehicle_base.stl" scale="0.001 0.001 0.001"/>
        </geometry>
        <material name="light_black"/>
      </visual>

      <collision>
        <origin xyz="-0.200 0 0.290" rpy="0 0 0"/>
        <geometry>
          <box size="0.290 0.400 0.580"/>
        </geometry>
      </collision>

      <inertial>
        <origin xyz="-0.177959 0 0.137067" rpy="0 0 0"/>
        <mass value="19.044577"/>
        <inertia ixx="467628328.712e-09" ixy="1161141.769e-09" ixz="-30628051.22e-09"
                 iyy="401596802.3e-09" iyz="-4237768.048e-09"
                 izz="311549116.3e-09" />
      </inertial>
    </link>

    <joint name="wheel_left_joint" type="continuous">
      <parent link="vehicle_base_link"/>
      <child link="wheel_left_link"/>
      <origin xyz="0.0 0.204 -0.02175" rpy="-1.57 0 0"/>
      <axis xyz="0 0 1"/>
      <dynamics damping="0.1" friction="2.0"/>
    </joint>

    <link name="wheel_left_link">
      <visual>
        <origin xyz="0 0 0" rpy="0 0 0"/>
        <geometry>
          <mesh filename="package://sciurus17_description/meshes/vehicle/wheels/left_tire_big.stl" scale="0.001 0.001 0.001"/>
        </geometry>
        <material name="dark"/>
      </visual>

      <collision>
        <origin xyz="0 0 0.010" rpy="0 0 0"/>
        <geometry>
          <cylinder length="0.025" radius="0.088"/>
        </geometry>
      </collision>

      <inertial>
        <origin xyz="0 0 0.007007" />
        <mass value="378.089e-03" />
        <inertia ixx="823382.354e-09" ixy="0.001e-9" ixz="0.0"
  		iyy="823382.325e-09" iyz="0.0"
  		izz="1625272.293e-09" />
        </inertial>
    </link>

    <joint name="wheel_right_joint" type="continuous">
      <parent link="vehicle_base_link"/>
      <child link="wheel_right_link"/>
      <origin xyz="0.0 -0.204 -0.02175" rpy="-1.57 0 0"/>
      <axis xyz="0 0 1"/>
      <dynamics damping="0.1" friction="2.0"/>
    </joint>

    <link name="wheel_right_link">
      <visual>
        <origin xyz="0 0 0" rpy="0 0 0"/>
        <geometry>
          <mesh filename="package://sciurus17_description/meshes/vehicle/wheels/right_tire_big.stl" scale="0.001 0.001 0.001"/>
        </geometry>
        <material name="dark"/>
      </visual>

      <collision>
        <origin xyz="0 0 -0.010" rpy="0 0 0"/>
        <geometry>
          <cylinder length="0.025" radius="0.088"/>
        </geometry>
      </collision>

      <inertial>
        <origin xyz="0 0 -0.007007" />
        <mass value="378.089e-03" />
        <inertia ixx="823382.354e-09" ixy="0.001e-9" ixz="0.0"
                  iyy="823382.325e-09" iyz="0.0"
                  izz="1625272.293e-09" />
      </inertial>

    </link>

    <joint name="caster_base_right_joint" type="fixed">
      <parent link="vehicle_base_link"/>
      <child link="caster_base_right_link"/>
      <origin xyz="-0.297 -0.1595 -0.01" rpy="0 0 0"/>
    </joint>

    <link name="caster_base_right_link">
      <visual>
        <origin xyz="0 0 0" rpy="3.14 0 0"/>
        <geometry>
          <mesh filename="package://sciurus17_description/meshes/vehicle/caster/caster_base.stl" scale="0.001 0.001 0.001"/>
        </geometry>
        <material name="dark"/>
      </visual>

      <collision>
        <origin xyz="0 0 0.010" rpy="0 0 0"/>
        <geometry>
          <box size="0.080 0.080 0.010"/>
        </geometry>
      </collision>

      <inertial>
        <origin xyz="0 0 5.268e-03" />
        <mass value="0.310" />
        <inertia ixx="105885e-09" ixy="0.0" ixz="0.0"
                 iyy="105885e-09" iyz="0.0"
                 izz="203743e-09" />
      </inertial>
    </link>

    <joint name="caster_body_right_joint" type="continuous">
      <parent link="caster_base_right_link"/>
      <child link="caster_body_right_link"/>
      <origin xyz="0 0 -0.013425" rpy="0 0 0"/>
      <axis xyz="0 0 1"/>
      <limit effort="0" velocity="0"/>
    </joint>

    <link name="caster_body_right_link">
      <visual>
        <origin xyz="0 0 0" rpy="-3.14 0 0"/>
        <geometry>
          <mesh filename="package://sciurus17_description/meshes/vehicle/caster/caster_body.stl" scale="0.001 0.001 0.001"/>
        </geometry>
        <material name="dark"/>
      </visual>

      <collision>
        <origin xyz="0 0.0 0" rpy="0 0 0"/>
        <geometry>
          <cylinder length="0.015" radius="0.035"/>
        </geometry>
      </collision>

      <inertial>
        <origin xyz="-14.063e-03 1.386e-03 20.078e-03" />
        <mass value="0.148" />
        <inertia ixx="108332e-09" ixy="2852e-09" ixz="25728e-09"
                 iyy="100089e-09" iyz="-6138e-09"
                 izz="95021e-09" />
      </inertial>
    </link>

    <joint name="caster_wheel_right_joint" type="continuous">
      <parent link="caster_body_right_link"/>
      <child link="caster_wheel_right_link"/>
      <origin xyz="-0.028 0 -0.049075" rpy="1.57 0 0"/>
      <axis xyz="0 0 1" />
      <limit effort="0" velocity="0"/>
    </joint>

    <link name="caster_wheel_right_link">
      <visual>
        <origin xyz="0 0 0" rpy="-3.14 0 0"/>
        <geometry>
          <mesh filename="package://sciurus17_description/meshes/vehicle/caster/caster_wheel.stl" scale="0.001 0.001 0.001"/>
        </geometry>
        <material name="dark"/>
      </visual>

      <collision>
        <origin xyz="0 0.0 0" rpy="0 0 0"/>
        <geometry>
          <cylinder length="0.032" radius="0.0375"/>
        </geometry>
      </collision>

      <inertial>
        <origin xyz="0 0 0" />
        <mass value="0.391" />
        <inertia ixx="108051e-09" ixy="0.0" ixz="0.0"
                 iyy="108051e-09" iyz="0.0"
                 izz="152231e-09" />
      </inertial>
    </link>

    <joint name="caster_base_left_joint" type="fixed">
      <parent link="vehicle_base_link"/>
      <child link="caster_base_left_link"/>
      <origin xyz="-0.297 0.1595 -0.01" rpy="0 0 0"/>
    </joint>

    <link name="caster_base_left_link">
      <visual>
        <origin xyz="0 0 0" rpy="3.14 0 0"/>
        <geometry>
          <mesh filename="package://sciurus17_description/meshes/vehicle/caster/caster_base.stl" scale="0.001 0.001 0.001"/>
        </geometry>
        <material name="dark"/>
      </visual>

      <collision>
        <origin xyz="0 0.001 0" rpy="0 0 0"/>
        <geometry>
          <box size="0.080 0.080 0.010"/>
        </geometry>
      </collision>

      <inertial>
        <origin xyz="0 0 5.268e-03" />
        <mass value="0.310" />
        <inertia ixx="105885e-09" ixy="0.0" ixz="0.0"
                 iyy="105885e-09" iyz="0.0"
                 izz="203743e-09" />
      </inertial>
    </link>

    <joint name="caster_body_left_joint" type="continuous">
      <parent link="caster_base_left_link"/>
      <child link="caster_body_left_link"/>
      <origin xyz="0 0 -0.013425" rpy="0 0 0"/>
      <axis xyz="0 0 1"/>
      <limit effort="0" velocity="0"/>
    </joint>

    <link name="caster_body_left_link">
      <visual>
        <origin xyz="0 0 0" rpy="3.14 0 0"/>
        <geometry>
          <mesh filename="package://sciurus17_description/meshes/vehicle/caster/caster_body.stl" scale="0.001 0.001 0.001"/>
        </geometry>
        <material name="dark"/>
      </visual>

      <collision>
        <origin xyz="0 0.0 0" rpy="0 0 0"/>
        <geometry>
          <cylinder length="0.015" radius="0.02"/>
        </geometry>
      </collision>

      <inertial>
        <origin xyz="-14.063e-03 1.386e-03 20.078e-03" />
        <mass value="0.148" />
        <inertia ixx="108332e-09" ixy="2852e-09" ixz="25728e-09"
                 iyy="100089e-09" iyz="-6138e-09"
                 izz="95021e-09" />
      </inertial>
    </link>

    <joint name="caster_wheel_left_joint" type="continuous">
      <axis xyz="0 0 1"/>
      <parent link="caster_body_left_link"/>
      <child link="caster_wheel_left_link"/>
      <origin xyz="-0.028 0 -0.049075" rpy="-1.57 0 0"/>
      <limit effort="0" velocity="0"/>
    </joint>

    <link name="caster_wheel_left_link">
      <visual>
        <origin xyz="0 0 0" rpy="0 0 0"/>
        <geometry>
          <mesh filename="package://sciurus17_description/meshes/vehicle/caster/caster_wheel.stl" scale="0.001 0.001 0.001"/>
        </geometry>
        <material name="dark"/>
      </visual>

      <collision>
        <origin xyz="0 0.0 0" rpy="0 0 0"/>
        <geometry>
          <cylinder length="0.032" radius="0.0375"/>
        </geometry>
      </collision>

      <inertial>
        <origin xyz="0 0 0" />
        <mass value="0.391" />
        <inertia ixx="108051e-09" ixy="0.0" ixz="0.0"
                 iyy="108051e-09" iyz="0.0"
                 izz="152231e-09" />
      </inertial>

    </link>


    <joint name="imu_joint" type="fixed">
      <parent link="vehicle_base_link"/>
      <child link="imu_link"/>
      <origin xyz="-0.032 0 0.068" rpy="0 0 0"/>
    </joint>

    <link name="imu_link"/>

    <joint name="scan_joint" type="fixed">
      <parent link="vehicle_base_link"/>
      <child link="base_scan"/>
      <origin xyz="0 0 0.1" rpy="0 0 0"/>
    </joint>

    <link name="base_scan">
      <visual>
        <origin xyz="0 0 0" rpy="0 0 0"/>
        <geometry>
          <mesh filename="package://sciurus17_description/meshes/vehicle/sensors/hokuyo.dae"/>
        </geometry>
        <material name="dark"/>
      </visual>

      <collision>
        <origin xyz="0 0 0" rpy="0 0 0" />
    		<geometry>
    			<mesh filename="package://sciurus17_description/meshes/vehicle/sensors/hokuyo_convex.dae" />
    		</geometry>
      </collision>

      <inertial>
        <mass value="0.114" />
        <origin xyz="0 0 0" />
        <inertia ixx="0.0" ixy="0.0" ixz="0.0"
                 iyy="0.0" iyz="0.0"
                 izz="0.0" />
      </inertial>
    </link>

    <joint name="sciurus17_joint" type="fixed">
      <parent link="base_footprint"/>
      <child link="sciurus17_base_link"/>
      <origin xyz="-0.1325 0 0.68975" rpy="0 0 0"/>
    </joint>

    <link name="sciurus17_base_link"/>
  </xacro:macro>
</robot>
